Workbook
Name DT.BREATH: Table5[DT.Breath]
Name DT.Patch: Table8[DT.Patch]
Name DT.Swab: Table6[DT.Swab]
Name DT.Sweat: Table9[DT.Sweat]
Name DT.Urine: Table7[DT.Urine]
Name EL: Sheet1!$AW$8:$AW$9
Name F: Sheet1!$AU$8:$AU$9
Name FS.IH: Table3[[#All],[Prep - Advance Cancel]]
Name FS.OH: Sheet2!$G$2:$G$5
Name H: Sheet1!$AT$8:$AT$9
Name M: Sheet1!$AQ$8:$AQ$9
Name O: Sheet1!$AS$8:$AS$9
Name PL: Sheet1!$AV$8:$AV$9
Name PT: Sheet2!$E$2:$E$6
Name S: Sheet1!$AR$8:$AR$9
Name T: Sheet1!$AP$8:$AP$9
Name table: Sheet1!$M$8:$P$97

Sheet Sheet1
A1: Version- 9.8 | AE1: * | AF1: 0.25 | AI1: Hours | AJ1: Minutes | AK1: Input hours and minutes to get total minutes. If you drive 1 hour 22 mins.
O2: Name: | S2: I certify these hours are true and accurate to the best of my knowledge. | AD2: =(1/1440*24) | AE2: 1 | AF2: 0.25 | AI2: 0.94375 | AJ2: =(AI2*1440)/24 | AK2: Input as 1:22 for total minutes of 82
M3: V=Vac | AD3: =(2/1440*24) | AE3: 2 | AF3: 0.25
M4: S=Sick | O4: Supervisor: | AD4: =(3/1440*24) | AE4: 3 | AF4: 0.25
M5: H=Holiday | AD5: =(4/1440*24) | AE5: 4 | AF5: 0.25
O6: Pay Period: | S6: Employee Signature/Date | AD6: =(5/1440*24) | AE6: 5 | AF6: 0.25
AD7: =(6/1440*24) | AE7: 6 | AF7: 0.25
A8: SERVICE TYPES | B8: SERVICE CHOICES PREP VIRTUAL | C8: TRAVEL COMMENTS | D8: Last Name, First Name Name of Client(s) | E8: Master Case # (will autofind by column D) | F8: Date of Service MM/DD/YY | G8: hrs:mins Time in | H8: hrs:mins Time out | I8: Drive From Address | J8: Drive To Address | K8: Miles | L8: Staff Name (First and Last Name Initials) | M8: Paid Leave (V, S, H) | N8: Paid Hours | O8: Meeting in hours | P8: Training in hours | Q8: Transport Bill Time (in hrs) | R8: Drive Non-Bill in hours | S8: Doc Time in hours | T8: Mileage Adjustment | U8: Odometer Start | V8: Odometer Stop | W8: Total Mileage | X8: Billable Hours | Y8: IndHrs - Drive Non-Bill | Z8: Indirect Hours | AA8: Drive Total (in hrs) | AB8: DAILY TOTAL | AC8: Mileage Reimb. | AD8: =(7/1440*24) | AE8: 7 | AF8: 0.25
E9: 466399 | Q9: =SUM(IF((OR(A9="Travel-PT",A9="Travel-FS-OH",A9="Travel-FS-IH")),(((((H9-G9)*1440)/24)*24)/1440*24),0)) | W9: =V9-U9 | X9: =SUM(IF((OR(G9="",H9="")),0,IF((H9<G9),(((H9-G9)*1440)/24)+24,(H9-G9)*1440)/24)*24)/1440*24 | Y9: =R9 | Z9: =(N9+O9+P9+S9) | AA9: =Q9+R9 | AB9: =N9+O9+P9+S9+X9+Y9 | AC9: =(W9-T9)*0.545 | AD9: =(8/1440*24) | AE9: 8 | AF9: 0.25
E10: 466399 | Q10: =SUM(IF((OR(A10="Travel-PT",A10="Travel-FS-OH",A10="Travel-FS-IH")),(((((H10-G10)*1440)/24)*24)/1440*24),0)) | W10: =V10-U10 | X10: =SUM(IF((OR(G10="",H10="")),0,IF((H10<G10),(((H10-G10)*1440)/24)+24,(H10-G10)*1440)/24)*24)/1440*24 | Y10: =R10 | Z10: =(N10+O10+P10+S10) | AA10: =Q10+R10 | AB10: =N10+O10+P10+S10+X10+Y10 | AC10: =(W10-T10)*0.545 | AD10: =(9/1440*24) | AE10: 9 | AF10: 0.25
E11: 466399 | Q11: =SUM(IF((OR(A11="Travel-PT",A11="Travel-FS-OH",A11="Travel-FS-IH")),(((((H11-G11)*1440)/24)*24)/1440*24),0)) | W11: =V11-U11 | X11: =SUM(IF((OR(G11="",H11="")),0,IF((H11<G11),(((H11-G11)*1440)/24)+24,(H11-G11)*1440)/24)*24)/1440*24 | Y11: =R11 | Z11: =(N11+O11+P11+S11) | AA11: =Q11+R11 | AB11: =N11+O11+P11+S11+X11+Y11 | AC11: =(W11-T11)*0.545 | AD11: =(10/1440*24) | AE11: 10 | AF11: 0.25
E12: =IFERROR(VLOOKUP(D12,Sheet3!A$1:B$50,2,FALSE),"") | Q12: =SUM(IF((OR(A12="Travel-PT",A12="Travel-FS-OH",A12="Travel-FS-IH")),(((((H12-G12)*1440)/24)*24)/1440*24),0)) | W12: =V12-U12 | X12: =SUM(IF((OR(G12="",H12="")),0,IF((H12<G12),(((H12-G12)*1440)/24)+24,(H12-G12)*1440)/24)*24)/1440*24 | Y12: =R12 | Z12: =(N12+O12+P12+S12) | AA12: =Q12+R12 | AB12: =N12+O12+P12+S12+X12+Y12 | AC12: =(W12-T12)*0.545 | AD12: =(11/1440*24) | AE12: 11 | AF12: 0.25
E13: 190820 | Q13: =SUM(IF((OR(A13="Travel-PT",A13="Travel-FS-OH",A13="Travel-FS-IH")),(((((H13-G13)*1440)/24)*24)/1440*24),0)) | W13: =V13-U13 | X13: =SUM(IF((OR(G13="",H13="")),0,IF((H13<G13),(((H13-G13)*1440)/24)+24,(H13-G13)*1440)/24)*24)/1440*24 | Y13: =R13 | Z13: =(N13+O13+P13+S13) | AA13: =Q13+R13 | AB13: =N13+O13+P13+S13+X13+Y13 | AC13: =(W13-T13)*0.545 | AD13: =(12/1440*24) | AE13: 12 | AF13: 0.25
E14: 190820 | Q14: =SUM(IF((OR(A14="Travel-PT",A14="Travel-FS-OH",A14="Travel-FS-IH")),(((((H14-G14)*1440)/24)*24)/1440*24),0)) | W14: =V14-U14 | X14: =SUM(IF((OR(G14="",H14="")),0,IF((H14<G14),(((H14-G14)*1440)/24)+24,(H14-G14)*1440)/24)*24)/1440*24 | Y14: =R14 | Z14: =(N14+O14+P14+S14) | AA14: =Q14+R14 | AB14: =N14+O14+P14+S14+X14+Y14 | AC14: =(W14-T14)*0.545 | AD14: =(13/1440*24) | AE14: 13 | AF14: 0.25
E15: 190820 | Q15: =SUM(IF((OR(A15="Travel-PT",A15="Travel-FS-OH",A15="Travel-FS-IH")),(((((H15-G15)*1440)/24)*24)/1440*24),0)) | W15: =V15-U15 | X15: =SUM(IF((OR(G15="",H15="")),0,IF((H15<G15),(((H15-G15)*1440)/24)+24,(H15-G15)*1440)/24)*24)/1440*24 | Y15: =R15 | Z15: =(N15+O15+P15+S15) | AA15: =Q15+R15 | AB15: =N15+O15+P15+S15+X15+Y15 | AC15: =(W15-T15)*0.545 | AD15: =(14/1440*24) | AE15: 14 | AF15: 0.25
E16: 190820 | Q16: =SUM(IF((OR(A16="Travel-PT",A16="Travel-FS-OH",A16="Travel-FS-IH")),(((((H16-G16)*1440)/24)*24)/1440*24),0)) | W16: =V16-U16 | X16: =SUM(IF((OR(G16="",H16="")),0,IF((H16<G16),(((H16-G16)*1440)/24)+24,(H16-G16)*1440)/24)*24)/1440*24 | Y16: =R16 | Z16: =(N16+O16+P16+S16) | AA16: =Q16+R16 | AB16: =N16+O16+P16+S16+X16+Y16 | AC16: =(W16-T16)*0.545 | AD16: =(15/1440*24) | AE16: 15 | AF16: 0.25
E17: =IFERROR(VLOOKUP(D17,Sheet3!A$1:B$50,2,FALSE),"") | Q17: =SUM(IF((OR(A17="Travel-PT",A17="Travel-FS-OH",A17="Travel-FS-IH")),(((((H17-G17)*1440)/24)*24)/1440*24),0)) | W17: =V17-U17 | X17: =SUM(IF((OR(G17="",H17="")),0,IF((H17<G17),(((H17-G17)*1440)/24)+24,(H17-G17)*1440)/24)*24)/1440*24 | Y17: =R17 | Z17: =(N17+O17+P17+S17) | AA17: =Q17+R17 | AB17: =N17+O17+P17+S17+X17+Y17 | AC17: =(W17-T17)*0.545 | AD17: =(16/1440*24) | AE17: 16 | AF17: 0.5
E18: 466399 | Q18: =SUM(IF((OR(A18="Travel-PT",A18="Travel-FS-OH",A18="Travel-FS-IH")),(((((H18-G18)*1440)/24)*24)/1440*24),0)) | W18: =V18-U18 | X18: =SUM(IF((OR(G18="",H18="")),0,IF((H18<G18),(((H18-G18)*1440)/24)+24,(H18-G18)*1440)/24)*24)/1440*24 | Y18: =R18 | Z18: =(N18+O18+P18+S18) | AA18: =Q18+R18 | AB18: =N18+O18+P18+S18+X18+Y18 | AC18: =(W18-T18)*0.545 | AD18: =(17/1440*24) | AE18: 17 | AF18: 0.5
E19: 466399 | Q19: =SUM(IF((OR(A19="Travel-PT",A19="Travel-FS-OH",A19="Travel-FS-IH")),(((((H19-G19)*1440)/24)*24)/1440*24),0)) | W19: =V19-U19 | X19: =SUM(IF((OR(G19="",H19="")),0,IF((H19<G19),(((H19-G19)*1440)/24)+24,(H19-G19)*1440)/24)*24)/1440*24 | Y19: =R19 | Z19: =(N19+O19+P19+S19) | AA19: =Q19+R19 | AB19: =N19+O19+P19+S19+X19+Y19 | AC19: =(W19-T19)*0.545 | AD19: =(18/1440*24) | AE19: 18 | AF19: 0.5
E20: 466399 | Q20: =SUM(IF((OR(A20="Travel-PT",A20="Travel-FS-OH",A20="Travel-FS-IH")),(((((H20-G20)*1440)/24)*24)/1440*24),0)) | W20: =V20-U20 | X20: =SUM(IF((OR(G20="",H20="")),0,IF((H20<G20),(((H20-G20)*1440)/24)+24,(H20-G20)*1440)/24)*24)/1440*24 | Y20: =R20 | Z20: =(N20+O20+P20+S20) | AA20: =Q20+R20 | AB20: =N20+O20+P20+S20+X20+Y20 | AC20: =(W20-T20)*0.545 | AD20: =(19/1440*24) | AE20: 19 | AF20: 0.5
E21: 466399 | Q21: =SUM(IF((OR(A21="Travel-PT",A21="Travel-FS-OH",A21="Travel-FS-IH")),(((((H21-G21)*1440)/24)*24)/1440*24),0)) | W21: =V21-U21 | X21: =SUM(IF((OR(G21="",H21="")),0,IF((H21<G21),(((H21-G21)*1440)/24)+24,(H21-G21)*1440)/24)*24)/1440*24 | Y21: =R21 | Z21: =(N21+O21+P21+S21) | AA21: =Q21+R21 | AB21: =N21+O21+P21+S21+X21+Y21 | AC21: =(W21-T21)*0.545
E22: 466399 | Q22: =SUM(IF((OR(A22="Travel-PT",A22="Travel-FS-OH",A22="Travel-FS-IH")),(((((H22-G22)*1440)/24)*24)/1440*24),0)) | W22: =V22-U22 | X22: =SUM(IF((OR(G22="",H22="")),0,IF((H22<G22),(((H22-G22)*1440)/24)+24,(H22-G22)*1440)/24)*24)/1440*24 | Y22: =R22 | Z22: =(N22+O22+P22+S22) | AA22: =Q22+R22 | AB22: =N22+O22+P22+S22+X22+Y22 | AC22: =(W22-T22)*0.545
E23: 466399 | Q23: =SUM(IF((OR(A23="Travel-PT",A23="Travel-FS-OH",A23="Travel-FS-IH")),(((((H23-G23)*1440)/24)*24)/1440*24),0)) | W23: =V23-U23 | X23: =SUM(IF((OR(G23="",H23="")),0,IF((H23<G23),(((H23-G23)*1440)/24)+24,(H23-G23)*1440)/24)*24)/1440*24 | Y23: =R23 | Z23: =(N23+O23+P23+S23) | AA23: =Q23+R23 | AB23: =N23+O23+P23+S23+X23+Y23 | AC23: =(W23-T23)*0.545
E24: 466399 | Q24: =SUM(IF((OR(A24="Travel-PT",A24="Travel-FS-OH",A24="Travel-FS-IH")),(((((H24-G24)*1440)/24)*24)/1440*24),0)) | W24: =V24-U24 | X24: =SUM(IF((OR(G24="",H24="")),0,IF((H24<G24),(((H24-G24)*1440)/24)+24,(H24-G24)*1440)/24)*24)/1440*24 | Y24: =R24 | Z24: =(N24+O24+P24+S24) | AA24: =Q24+R24 | AB24: =N24+O24+P24+S24+X24+Y24 | AC24: =(W24-T24)*0.545
E25: 466399 | Q25: =SUM(IF((OR(A25="Travel-PT",A25="Travel-FS-OH",A25="Travel-FS-IH")),(((((H25-G25)*1440)/24)*24)/1440*24),0)) | W25: =V25-U25 | X25: =SUM(IF((OR(G25="",H25="")),0,IF((H25<G25),(((H25-G25)*1440)/24)+24,(H25-G25)*1440)/24)*24)/1440*24 | Y25: =R25 | Z25: =(N25+O25+P25+S25) | AA25: =Q25+R25 | AB25: =N25+O25+P25+S25+X25+Y25 | AC25: =(W25-T25)*0.545
E26: 466399 | Q26: =SUM(IF((OR(A26="Travel-PT",A26="Travel-FS-OH",A26="Travel-FS-IH")),(((((H26-G26)*1440)/24)*24)/1440*24),0)) | W26: =V26-U26 | X26: =SUM(IF((OR(G26="",H26="")),0,IF((H26<G26),(((H26-G26)*1440)/24)+24,(H26-G26)*1440)/24)*24)/1440*24 | Y26: =R26 | Z26: =(N26+O26+P26+S26) | AA26: =Q26+R26 | AB26: =N26+O26+P26+S26+X26+Y26 | AC26: =(W26-T26)*0.545
E27: 466399 | Q27: =SUM(IF((OR(A27="Travel-PT",A27="Travel-FS-OH",A27="Travel-FS-IH")),(((((H27-G27)*1440)/24)*24)/1440*24),0)) | W27: =V27-U27 | X27: =SUM(IF((OR(G27="",H27="")),0,IF((H27<G27),(((H27-G27)*1440)/24)+24,(H27-G27)*1440)/24)*24)/1440*24 | Y27: =R27 | Z27: =(N27+O27+P27+S27) | AA27: =Q27+R27 | AB27: =N27+O27+P27+S27+X27+Y27 | AC27: =(W27-T27)*0.545
E28: 466399 | Q28: =SUM(IF((OR(A28="Travel-PT",A28="Travel-FS-OH",A28="Travel-FS-IH")),(((((H28-G28)*1440)/24)*24)/1440*24),0)) | W28: =V28-U28 | X28: =SUM(IF((OR(G28="",H28="")),0,IF((H28<G28),(((H28-G28)*1440)/24)+24,(H28-G28)*1440)/24)*24)/1440*24 | Y28: =R28 | Z28: =(N28+O28+P28+S28) | AA28: =Q28+R28 | AB28: =N28+O28+P28+S28+X28+Y28 | AC28: =(W28-T28)*0.545
E29: 466399 | Q29: =SUM(IF((OR(A29="Travel-PT",A29="Travel-FS-OH",A29="Travel-FS-IH")),(((((H29-G29)*1440)/24)*24)/1440*24),0)) | W29: =V29-U29 | X29: =SUM(IF((OR(G29="",H29="")),0,IF((H29<G29),(((H29-G29)*1440)/24)+24,(H29-G29)*1440)/24)*24)/1440*24 | Y29: =R29 | Z29: =(N29+O29+P29+S29) | AA29: =Q29+R29 | AB29: =N29+O29+P29+S29+X29+Y29 | AC29: =(W29-T29)*0.545
E30: 466399 | Q30: =SUM(IF((OR(A30="Travel-PT",A30="Travel-FS-OH",A30="Travel-FS-IH")),(((((H30-G30)*1440)/24)*24)/1440*24),0)) | W30: =V30-U30 | X30: =SUM(IF((OR(G30="",H30="")),0,IF((H30<G30),(((H30-G30)*1440)/24)+24,(H30-G30)*1440)/24)*24)/1440*24 | Y30: =R30 | Z30: =(N30+O30+P30+S30) | AA30: =Q30+R30 | AB30: =N30+O30+P30+S30+X30+Y30 | AC30: =(W30-T30)*0.545
E31: 466399 | Q31: =SUM(IF((OR(A31="Travel-PT",A31="Travel-FS-OH",A31="Travel-FS-IH")),(((((H31-G31)*1440)/24)*24)/1440*24),0)) | W31: =V31-U31 | X31: =SUM(IF((OR(G31="",H31="")),0,IF((H31<G31),(((H31-G31)*1440)/24)+24,(H31-G31)*1440)/24)*24)/1440*24 | Y31: =R31 | Z31: =(N31+O31+P31+S31) | AA31: =Q31+R31 | AB31: =N31+O31+P31+S31+X31+Y31 | AC31: =(W31-T31)*0.545
E32: 466399 | Q32: =SUM(IF((OR(A32="Travel-PT",A32="Travel-FS-OH",A32="Travel-FS-IH")),(((((H32-G32)*1440)/24)*24)/1440*24),0)) | W32: =V32-U32 | X32: =SUM(IF((OR(G32="",H32="")),0,IF((H32<G32),(((H32-G32)*1440)/24)+24,(H32-G32)*1440)/24)*24)/1440*24 | Y32: =R32 | Z32: =(N32+O32+P32+S32) | AA32: =Q32+R32 | AB32: =N32+O32+P32+S32+X32+Y32 | AC32: =(W32-T32)*0.545
... E34: 466399 | Q34: =SUM(IF((OR(A34="Travel-PT",A34="Travel-FS-OH",A34="Travel-FS-IH")),(((((H34-G34)*1440)/24)*24)/1440*24),0)) | W34: =V34-U34 | X34: =SUM(IF((OR(G34="",H34="")),0,IF((H34<G34),(((H34-G34)*1440)/24)+24,(H34-G34)*1440)/24)*24)/1440*24 | Y34: =R34 | Z34: =(N34+O34+P34+S34) | AA34: =Q34+R34 | AB34: =N34+O34+P34+S34+X34+Y34 | AC34: =(W34-T34)*0.545
E35: 466399 | Q35: =SUM(IF((OR(#REF!="Travel-PT",#REF!="Travel-FS-OH",#REF!="Travel-FS-IH")),(((((H35-G35)*1440)/24)*24)/1440*24),0)) | W35: =V35-U35 | X35: =SUM(IF((OR(G35="",H35="")),0,IF((H35<G35),(((H35-G35)*1440)/24)+24,(H35-G35)*1440)/24)*24)/1440*24 | Y35: =R35 | Z35: =(N35+O35+P35+S35) | AA35: =Q35+R35 | AB35: =N35+O35+P35+S35+X35+Y35 | AC35: =(W35-T35)*0.545
E36: =IFERROR(VLOOKUP(D36,Sheet3!A$1:B$50,2,FALSE),"") | Q36: =SUM(IF((OR(A35="Travel-PT",A35="Travel-FS-OH",A35="Travel-FS-IH")),(((((H36-G36)*1440)/24)*24)/1440*24),0)) | W36: =V36-U36 | X36: =SUM(IF((OR(G36="",H36="")),0,IF((H36<G36),(((H36-G36)*1440)/24)+24,(H36-G36)*1440)/24)*24)/1440*24 | Y36: =R36 | Z36: =(N36+O36+P36+S36) | AA36: =Q36+R36 | AB36: =N36+O36+P36+S36+X36+Y36 | AC36: =(W36-T36)*0.545
E37: =IFERROR(VLOOKUP(D37,Sheet3!A$1:B$50,2,FALSE),"") | Q37: =SUM(IF((OR(A37="Travel-PT",A37="Travel-FS-OH",A37="Travel-FS-IH")),(((((H37-G37)*1440)/24)*24)/1440*24),0)) | W37: =V37-U37 | X37: =SUM(IF((OR(G37="",H37="")),0,IF((H37<G37),(((H37-G37)*1440)/24)+24,(H37-G37)*1440)/24)*24)/1440*24 | Y37: =R37 | Z37: =(N37+O37+P37+S37) | AA37: =Q37+R37 | AB37: =N37+O37+P37+S37+X37+Y37 | AC37: =(W37-T37)*0.545
E38: =IFERROR(VLOOKUP(D38,Sheet3!A$1:B$50,2,FALSE),"") | Q38: =SUM(IF((OR(A38="Travel-PT",A38="Travel-FS-OH",A38="Travel-FS-IH")),(((((H38-G38)*1440)/24)*24)/1440*24),0)) | W38: =V38-U38 | X38: =SUM(IF((OR(G38="",H38="")),0,IF((H38<G38),(((H38-G38)*1440)/24)+24,(H38-G38)*1440)/24)*24)/1440*24 | Y38: =R38 | Z38: =(N38+O38+P38+S38) | AA38: =Q38+R38 | AB38: =N38+O38+P38+S38+X38+Y38 | AC38: =(W38-T38)*0.545
E39: =IFERROR(VLOOKUP(D39,Sheet3!A$1:B$50,2,FALSE),"") | Q39: =SUM(IF((OR(A39="Travel-PT",A39="Travel-FS-OH",A39="Travel-FS-IH")),(((((H39-G39)*1440)/24)*24)/1440*24),0)) | W39: =V39-U39 | X39: =SUM(IF((OR(G39="",H39="")),0,IF((H39<G39),(((H39-G39)*1440)/24)+24,(H39-G39)*1440)/24)*24)/1440*24 | Y39: =R39 | Z39: =(N39+O39+P39+S39) | AA39: =Q39+R39 | AB39: =N39+O39+P39+S39+X39+Y39 | AC39: =(W39-T39)*0.545
E40: =IFERROR(VLOOKUP(D40,Sheet3!A$1:B$50,2,FALSE),"") | Q40: =SUM(IF((OR(A40="Travel-PT",A40="Travel-FS-OH",A40="Travel-FS-IH")),(((((H40-G40)*1440)/24)*24)/1440*24),0)) | W40: =V40-U40 | X40: =SUM(IF((OR(G40="",H40="")),0,IF((H40<G40),(((H40-G40)*1440)/24)+24,(H40-G40)*1440)/24)*24)/1440*24 | Y40: =R40 | Z40: =(N40+O40+P40+S40) | AA40: =Q40+R40 | AB40: =N40+O40+P40+S40+X40+Y40 | AC40: =(W40-T40)*0.545
E41: =IFERROR(VLOOKUP(D41,Sheet3!A$1:B$50,2,FALSE),"") | Q41: =SUM(IF((OR(A41="Travel-PT",A41="Travel-FS-OH",A41="Travel-FS-IH")),(((((H41-G41)*1440)/24)*24)/1440*24),0)) | W41: =V41-U41 | X41: =SUM(IF((OR(G41="",H41="")),0,IF((H41<G41),(((H41-G41)*1440)/24)+24,(H41-G41)*1440)/24)*24)/1440*24 | Y41: =R41 | Z41: =(N41+O41+P41+S41) | AA41: =Q41+R41 | AB41: =N41+O41+P41+S41+X41+Y41 | AC41: =(W41-T41)*0.545
...

Sheet Sheet2
A1: MAIN LIST | E1: PT LIST | G1: FS-OH LIST | I1: FS-IH LIST
A2: PT | B2: 8873 | E2: Prep - Advance Cancel | G2: Prep - Advance Cancel | I2: Prep - Advance Cancel
A3: Travel-PT | B3: 9789 | E3: Prep - Enroute Cancel | G3: Prep - Enroute Cancel | I3: Prep - Enroute Cancel
A4: Travel-PT-Kids | B4: 3773 | E4: Prep - No Show | G4: Prep - No Show | I4: Prep - No Show
A5: FS.OH | B5: 7443 | E5: Virtual | G5: Virtual | I5: Virtual
A6: Travel-FS-OH | B6: 2178
A7: FS.IH | B7: 7171
A8: Travel-FS-IH | B8: 2178 | E8: DT.Breath | G8: DT.Swab | I8: DT.Urine | K8: DT.Patch | M8: DT.Sweat
A9: DT.Breath | E9: Admission | G9: Admission | I9: Admission | K9: Admission | M9: Admission
A10: DT.Swab | E10: Refusal | G10: Refusal | I10: Refusal | K10: Refusal | M10: Refusal
A11: DT.Urine | E11: No Show | G11: No Show | I11: No Show | K11: No Show | M11: No Show
A12: DT.Patch | E12: Negative | G12: Negative | I12: Negative | K12: Negative | M12: Negative
A13: DT.Sweat | E13: Positive for: | G13: Positive for: | I13: Positive for: | K13: Positive for: | M13: Positive for:
E18: STAFF NAMES
A19: DT - Breath | B19: Admission | C19: 15 | E19: Brenda Russell | F19: BR
A20: DT - Swab | B20: Refusal | C20: 15 | E20: Sheila Decker | F20: SD
A21: DT - Urine | B21: No Show | C21: 15 | E21: Pamela Spier-Edmond | F21: PSE
A22: DT - Patch | B22: Negative | C22: 60 | E22: Amanda Weinman | F22: AW
A23: DT - Sweat | B23: Positive for: | C23: 60 | E23: Kris Zeilinger | F23: KZ
E24: Kyle Fox | F24: KF
A25: PT | B25: Prep - Advance Cancellation | C25: 23.5 | E25: Payton Kelly | F25: PK
A26: FS-OH | B26: Prep - Enroute Cancellation | C26: 23.5 | E26: Ronda Cary | F26: RC
A27: FS-IH | B27: Prep - No Show | C27: 23.5 | E27: Sheila Decker | F27: SD
B28: Completed | C28: 47
A30: Comment Box
A31: Enroute Cancel
A32: No Show

Sheet Sheet3
A1: Arou, Agom | B1: 483451
A2: Bartels, Ashley | B2: 698929
A3: Blackeagle, Heather | B3: 162201
A4: Goin, Cierra | B4: 535539
A5: Goodface, Ryan | B5: 334070
A6: Hamner, Jammie | B6: 604045
A7: Harris, Shawntia | B7: 538121
A8: Hussein, Amina | B8: 505390
A9: May, Jalisa | B9: 548161
A10: May, Jalisa | B10: 548161
A11: May, Michael | B11: 548161
A12: Morris, Kyla | B12: 667125
... A15: Wilson, Quianna | B15: 663042
